[2024-02-05T23:27:35.680+0000] {taskinstance.py:1956} INFO - Dependencies all met for dep_context=non-requeueable deps ti=<TaskInstance: git_repo_dag.list_repo_tags manual__2024-02-05T23:27:31.303193+00:00 [queued]>
[2024-02-05T23:27:35.696+0000] {taskinstance.py:1956} INFO - Dependencies all met for dep_context=requeueable deps ti=<TaskInstance: git_repo_dag.list_repo_tags manual__2024-02-05T23:27:31.303193+00:00 [queued]>
[2024-02-05T23:27:35.696+0000] {taskinstance.py:2170} INFO - Starting attempt 1 of 1
[2024-02-05T23:27:35.731+0000] {taskinstance.py:2191} INFO - Executing <Task(GithubOperator): list_repo_tags> on 2024-02-05 23:27:31.303193+00:00
[2024-02-05T23:27:35.734+0000] {standard_task_runner.py:60} INFO - Started process 177 to run task
[2024-02-05T23:27:35.737+0000] {standard_task_runner.py:87} INFO - Running: ['airflow', 'tasks', 'run', 'git_repo_dag', 'list_repo_tags', 'manual__2024-02-05T23:27:31.303193+00:00', '--job-id', '29', '--raw', '--subdir', 'DAGS_FOLDER/git_repo_dag.py', '--cfg-path', '/tmp/tmpnu6ltphf']
[2024-02-05T23:27:35.738+0000] {standard_task_runner.py:88} INFO - Job 29: Subtask list_repo_tags
[2024-02-05T23:27:35.817+0000] {task_command.py:423} INFO - Running <TaskInstance: git_repo_dag.list_repo_tags manual__2024-02-05T23:27:31.303193+00:00 [running]> on host b76a52ce58ff
[2024-02-05T23:27:35.951+0000] {taskinstance.py:2480} INFO - Exporting env vars: AIRFLOW_CTX_DAG_OWNER='airflow' AIRFLOW_CTX_DAG_ID='git_repo_dag' AIRFLOW_CTX_TASK_ID='list_repo_tags' AIRFLOW_CTX_EXECUTION_DATE='2024-02-05T23:27:31.303193+00:00' AIRFLOW_CTX_TRY_NUMBER='1' AIRFLOW_CTX_DAG_RUN_ID='manual__2024-02-05T23:27:31.303193+00:00'
[2024-02-05T23:27:35.966+0000] {base.py:83} INFO - Using connection ID 'github_default' for task execution.
[2024-02-05T23:27:36.741+0000] {taskinstance.py:2698} ERROR - Task failed with exception
Traceback (most recent call last):
  File "/home/airflow/.local/lib/python3.8/site-packages/airflow/providers/github/operators/github.py", line 70, in execute
    github_result = getattr(resource, self.method_name)(**self.github_method_args)
  File "/home/airflow/.local/lib/python3.8/site-packages/github/MainClass.py", line 427, in get_repo
    headers, data = self.__requester.requestJsonAndCheck("GET", url)
  File "/home/airflow/.local/lib/python3.8/site-packages/github/Requester.py", line 537, in requestJsonAndCheck
    return self.__check(*self.requestJson(verb, url, parameters, headers, input, self.__customConnection(url)))
  File "/home/airflow/.local/lib/python3.8/site-packages/github/Requester.py", line 598, in __check
    raise self.createException(status, responseHeaders, data)
github.GithubException.UnknownObjectException: 404 {"message": "Not Found", "documentation_url": "https://docs.github.com/rest/repos/repos#get-a-repository"}

During handling of the above exception, another exception occurred:

Traceback (most recent call last):
  File "/home/airflow/.local/lib/python3.8/site-packages/airflow/models/taskinstance.py", line 433, in _execute_task
    result = execute_callable(context=context, **execute_callable_kwargs)
  File "/home/airflow/.local/lib/python3.8/site-packages/airflow/providers/github/operators/github.py", line 77, in execute
    raise AirflowException(f"Failed to execute GithubOperator, error: {github_error}")
airflow.exceptions.AirflowException: Failed to execute GithubOperator, error: 404 {"message": "Not Found", "documentation_url": "https://docs.github.com/rest/repos/repos#get-a-repository"}
[2024-02-05T23:27:36.746+0000] {taskinstance.py:1138} INFO - Marking task as FAILED. dag_id=git_repo_dag, task_id=list_repo_tags, execution_date=20240205T232731, start_date=20240205T232735, end_date=20240205T232736
[2024-02-05T23:27:36.774+0000] {standard_task_runner.py:107} ERROR - Failed to execute job 29 for task list_repo_tags (Failed to execute GithubOperator, error: 404 {"message": "Not Found", "documentation_url": "https://docs.github.com/rest/repos/repos#get-a-repository"}; 177)
[2024-02-05T23:27:36.797+0000] {local_task_job_runner.py:234} INFO - Task exited with return code 1
[2024-02-05T23:27:36.820+0000] {taskinstance.py:3280} INFO - 0 downstream tasks scheduled from follow-on schedule check
